Workbook

Sheet 純數字
C2: 2023 | O2: 2024 | AB2: 2025 | AO2: 2026
C3: 1月 | D3: 2月 | E3: 3月 | F3: 4月 | G3: 5月 | H3: 6月 | I3: 7月 | J3: 8月 | K3: 9月 | L3: 10月 | M3: 11月 | N3: 12月 | O3: 1月 | P3: 2月 | Q3: 3月 | R3: 4月 | S3: 5月 | T3: 6月 | U3: 7月 | V3: 8月 | W3: 9月 | X3: 10月 | Y3: 11月 | Z3: 12月 | AB3: 1月 | AC3: 2月 | AD3: 3月 | AE3: 4月 | AF3: 5月 | AG3: 6月 | AH3: 7月 | AI3: 8月 | AJ3: 9月 | AK3: 10月 | AL3: 11月 | AM3: 12月 | AO3: 1月 | AP3: 2月 | AQ3: 3月 | AR3: 4月 | AS3: 5月 | AT3: 6月 | AU3: 7月 | AV3: 8月 | AW3: 9月 | AX3: 10月 | AY3: 11月 | AZ3: 12月
A4: Total revenue | B4: 合併營收 | C4: =raw!B32 -> 14814.979 | D4: =raw!C32 -> 13735.483 | E4: =raw!D32 -> 14464.876 | F4: =raw!E32 -> 13685.917 | G4: =raw!F32 -> 14776.841 | H4: =raw!G32 -> 15083.561 | I4: =raw!H32 -> 14274.764 | J4: =raw!I32 -> 14561.723 | ... N4: =raw!M32 -> 17080.887 | O4: =raw!O32 -> 16958.579 | P4: =raw!P32 -> 15247.918 | Q4: =raw!Q32 -> 16070.134 | R4: =raw!R32 -> 15042.779 | S4: =raw!S32 -> 16031.947 | T4: =raw!T32 -> 16669.17 | U4: =raw!U32 -> 15470.631 | V4: =raw!V32 -> 15817.81 | ... Z4: =raw!Z32 -> 17156.531 | AB4: =raw!AB32 -> 16461.916 | AC4: =raw!AC32 -> 15528.063 | AD4: =raw!AD32 -> 16177.374 | AE4: =raw!AE32 -> 15393.306 | AF4: =raw!AF32 -> 15823.032 | AG4: =raw!AG32 -> 16254.676 | AH4: =raw!AH32 -> 15092.708 | AI4: =raw!AI32 -> 15468.138 | ... AM4: =raw!AM32 -> 18049.316 | AO4: =raw!AO32 -> 17145.458 | AP4: =raw!AP32 -> 15523.554 | AQ4: =raw!AQ32 -> 17109.29 | AR4: =raw!AR32 -> 15669.305 | AS4: =raw!AS32 -> 16440.683 | AT4: =raw!AT32 -> 0 | AU4: =raw!AU32 -> 0 | AV4: =raw!AV32 -> 0 | ... AZ4: =raw!AZ32 -> 0
A5: EBITDA | B5: 稅息折舊及攤銷前利潤 | C5: =raw!B33 -> 2886.7427 | D5: =raw!C33 -> 2839.2053 | E5: =raw!D33 -> 2956.4667 | F5: =raw!E33 -> 2856.637 | G5: =raw!F33 -> 2954.84 | H5: =raw!G33 -> 3095.2013 | I5: =raw!H33 -> 2961.5653 | J5: =raw!I33 -> 2953.7084 | ... N5: =raw!M33 -> 3519.4083 | O5: =raw!O33 -> 3675.2648 | P5: =raw!P33 -> 3331.6564 | Q5: =raw!Q33 -> 3580.5579 | R5: =raw!R33 -> 3484.0874 | S5: =raw!S33 -> 3490.7401 | T5: =raw!T33 -> 3611.585 | U5: =raw!U33 -> 3513.0108 | V5: =raw!V33 -> 3562.6663 | ... Z5: =raw!Z33 -> 3496.6582 | AB5: =raw!AB33 -> 3590.6773 | AC5: =raw!AC33 -> 3469.5616 | AD5: =raw!AD33 -> 3494.1166 | AE5: =raw!AE33 -> 3437.9751 | AF5: =raw!AF33 -> 3496.4753 | AG5: =raw!AG33 -> 3654.4695 | AH5: =raw!AH33 -> 3575.9519 | AI5: =raw!AI33 -> 3561.4542 | ... AM5: =raw!AM33 -> 3959.8724 | AO5: =raw!AO33 -> 3871.9103 | AP5: =raw!AP33 -> 3584.663 | AQ5: =raw!AQ33 -> 3897.3167 | AR5: =raw!AR33 -> 3787.6145 | AS5: =raw!AS33 -> 3834.421 | AT5: =raw!AT33 -> 0 | AU5: =raw!AU33 -> 0 | AV5: =raw!AV33 -> 0 | ... AZ5: =raw!AZ33 -> 0
A6: Operating income | B6: 營業利益 | C6: =raw!B34 -> 1421.5408 | D6: =raw!C34 -> 1376.0586 | E6: =raw!D34 -> 1491.994 | F6: =raw!E34 -> 1384.1967 | G6: =raw!F34 -> 1480.0763 | H6: =raw!G34 -> 1616.0188 | I6: =raw!H34 -> 1477.8706 | J6: =raw!I34 -> 1470.0406 | ... N6: =raw!M34 -> 1533.0298 | O6: =raw!O34 -> 1658.162 | P6: =raw!P34 -> 1356.9527 | Q6: =raw!Q34 -> 1640.184 | R6: =raw!R34 -> 1588.2351 | S6: =raw!S34 -> 1601.4553 | T6: =raw!T34 -> 1761.2851 | U6: =raw!U34 -> 1691.2153 | V6: =raw!V34 -> 1798.2882 | ... Z6: =raw!Z34 -> 1731.3535 | AB6: =raw!AB34 -> 1781.3637 | AC6: =raw!AC34 -> 1668.8929 | AD6: =raw!AD34 -> 1699.3014 | AE6: =raw!AE34 -> 1630.7075 | AF6: =raw!AF34 -> 1691.6897 | AG6: =raw!AG34 -> 1846.0869 | AH6: =raw!AH34 -> 1733.4937 | AI6: =raw!AI34 -> 1725.4035 | ... AM6: =raw!AM34 -> 2169.0488 | AO6: =raw!AO34 -> 2061.9759 | AP6: =raw!AP34 -> 1776.3403 | AQ6: =raw!AQ34 -> 2094.4303 | AR6: =raw!AR34 -> 1989.422 | AS6: =raw!AS34 -> 2043.5707 | AT6: =raw!AT34 -> 0 | AU6: =raw!AU34 -> 0 | AV6: =raw!AV34 -> 0 | ... AZ6: =raw!AZ34 -> 0
A7: Net income | B7: 稅後淨利 | C7: =raw!B37 -> 844.98642 | D7: =raw!C37 -> 925.57407 | E7: =raw!D37 -> 944.15381 | F7: =raw!E37 -> 954.9249 | G7: =raw!F37 -> 971.7405 | H7: =raw!G37 -> 1108.6137 | I7: =raw!H37 -> 1010.5131 | J7: =raw!I37 -> 1049.6967 | ... N7: =raw!M37 -> 1770.4948 | O7: =raw!O37 -> 1055.3977 | P7: =raw!P37 -> 882.42083 | Q7: =raw!Q37 -> 1030.1014 | R7: =raw!R37 -> 1066.945 | S7: =raw!S37 -> 1031.2977 | T7: =raw!T37 -> 1134.3589 | U7: =raw!U37 -> 1836.7955 | V7: =raw!V37 -> 1153.2637 | ... Z7: =raw!Z37 -> 949.26534 | AB7: =raw!AB37 -> 1162.2662 | AC7: =raw!AC37 -> 1254.8655 | AD7: =raw!AD37 -> 1238.0669 | AE7: =raw!AE37 -> 1043.4317 | AF7: =raw!AF37 -> 1004.826 | AG7: =raw!AG37 -> 1240.9329 | AH7: =raw!AH37 -> 1203.2303 | AI7: =raw!AI37 -> 1262.893 | ... AM7: =raw!AM37 -> 1322.2063 | AO7: =raw!AO37 -> 1406.2327 | AP7: =raw!AP37 -> 1240.8602 | AQ7: =raw!AQ37 -> 1499.2274 | AR7: =raw!AR37 -> 1425.7521 | AS7: =raw!AS37 -> 1516.3126 | AT7: =raw!AT37 -> 0 | AU7: =raw!AU37 -> 0 | AV7: =raw!AV37 -> 0 | ... AZ7: =raw!AZ37 -> 0
A8: EPS (NT$) | B8: EPS (NT$) | C8: =raw!B38 -> 0 | D8: =raw!C38 -> 0 | E8: =raw!D38 -> 0 | F8: =raw!E38 -> 0 | G8: =raw!F38 -> 0 | H8: =raw!G38 -> 0 | I8: =raw!H38 -> 0 | J8: =raw!I38 -> 0 | ... N8: =raw!M38 -> 0 | O8: 0.35 | P8: 0.29 | Q8: 0.34 | R8: 0.35 | S8: 0.35 | T8: =raw!T38 -> 0.37 | U8: 0.61 | V8: =raw!V38 -> 0.38 | W8: 0.39 | X8: 0.39 | Y8: 0.43 | Z8: 0.32 | AB8: =raw!AB38 -> 0.38 | AC8: 0.42 | AD8: 0.41 | AE8: 0.34 | AF8: 0.34 | AG8: =raw!AG38 -> 0.41 | AH8: =raw!AH38 -> 0.39 | AI8: =raw!AI38 -> 0.42 | AJ8: =raw!AJ38 -> 0.38 | AK8: =raw!AK38 -> 0.38 | AL8: =raw!AL38 -> 0.47 | AM8: =raw!AM38 -> 0.43 | AO8: =raw!AO38 -> 0.46 | AP8: =raw!AP38 -> 0.42 | AQ8: =raw!AQ38 -> 0.49 | AR8: =raw!AR38 -> 0.47 | AS8: =raw!AS38 -> 0.5 | AT8: =raw!AT38 -> 0 | AU8: =raw!AU38 -> 0 | AV8: =raw!AV38 -> 0 | ... AZ8: =raw!AZ38 -> 0
A9: Pre-tax income | B9: 稅前利潤 | C9: =raw!B35 -> 1299.9049 | D9: =raw!C35 -> 1339.4023 | E9: =raw!D35 -> 1421.376 | F9: =raw!E35 -> 1340.0058 | G9: =raw!F35 -> 1399.1266 | H9: =raw!G35 -> 1605.5319 | I9: =raw!H35 -> 1438.1465 | J9: =raw!I35 -> 1408.7778 | ... N9: =raw!M35 -> 2177.1993 | O9: =raw!O35 -> 1566.2901 | P9: =raw!P35 -> 1259.4209 | Q9: =raw!Q35 -> 1496.0923 | R9: =raw!R35 -> 1490.0255 | S9: =raw!S35 -> 1449.3426 | T9: =raw!T35 -> 1619.3797 | U9: =raw!U35 -> 2472.4766 | V9: =raw!V35 -> 1599.7771 | ... Z9: =raw!Z35 -> 1349.2449 | AB9: =raw!AB35 -> 1640.553 | AC9: =raw!AC35 -> 1560.4297 | AD9: =raw!AD35 -> 1709.8262 | AE9: =raw!AE35 -> 1445.6731 | AF9: =raw!AF35 -> 1413.1855 | AG9: =raw!AG35 -> 1694.8403 | AH9: =raw!AH35 -> 1643.4936 | AI9: =raw!AI35 -> 1689.5503 | ... AM9: =raw!AM35 -> 1945.4288 | AO9: =raw!AO35 -> 1964.9515 | AP9: =raw!AP35 -> 1664.0097 | AQ9: =raw!AQ35 -> 2039.9491 | AR9: =raw!AR35 -> 1917.3062 | AS9: =raw!AS35 -> 1968.856 | AT9: =raw!AT35 -> 0 | AU9: =raw!AU35 -> 0 | AV9: =raw!AV35 -> 0 | ... AZ9: =raw!AZ35 -> 0
A10: Pre-tax income margin | B10: 稅前淨利率 | C10: =raw!B36 -> 0.087742609 | D10: =raw!C36 -> 0.097514027 | E10: =raw!D36 -> 0.09826396 | F10: =raw!E36 -> 0.097911289 | G10: =raw!F36 -> 0.094683741 | H10: =raw!G36 -> 0.1064425 | I10: =raw!H36 -> 0.10074748 | J10: =raw!I36 -> 0.096745269 | ... N10: =raw!M36 -> 0.12746407 | O10: =raw!O36 -> 0.092359747 | P10: =raw!P36 -> 0.082596257 | Q10: =raw!Q36 -> 0.093097683 | R10: =raw!R36 -> 0.099052546 | S10: =raw!S36 -> 0.090403407 | T10: =raw!T36 -> 0.097148189 | U10: =raw!U36 -> 0.15981743 | V10: =raw!V36 -> 0.10113771 | ... Z10: =raw!Z36 -> 0.078643224 | AB10: =raw!AB36 -> 0.099657473 | AC10: =raw!AC36 -> 0.10049095 | AD10: =raw!AD36 -> 0.10569244 | AE10: =raw!AE36 -> 0.093915694 | AF10: =raw!AF36 -> 0.089311929 | AG10: =raw!AG36 -> 0.10426786 | AH10: =raw!AH36 -> 0.10889322 | AI10: =raw!AI36 -> 0.10922778 | ... AM10: =raw!AM36 -> 0.10778407 | AO10: =raw!AO36 -> 0.11460478 | AP10: =raw!AP36 -> 0.10719257 | AQ10: =raw!AQ36 -> 0.1192305 | AR10: =raw!AR36 -> 0.12236065 | AS10: =raw!AS36 -> 0.11975512 | AT10: =raw!AT36 -> 0 | AU10: =raw!AU36 -> 0 | AV10: =raw!AV36 -> 0 | ... AZ10: =raw!AZ36 -> 0
A11: Cumulative weighted-average outstanding shares (m) | B11: Cumulative weighted-average outstanding shares (m) | C11: =raw!B39 -> 2820.482 | D11: =raw!C39 -> 2820.482 | E11: =raw!D39 -> 2820.482 | F11: =raw!E39 -> 2820.482 | G11: =raw!F39 -> 2820.482 | H11: =raw!G39 -> 2820.482 | I11: =raw!H39 -> 2820.482 | J11: =raw!I39 -> 2820.482 | ... N11: =raw!M39 -> 2837.8104 | O11: =raw!O39 -> 3024.5102 | P11: =raw!P39 -> 3024.5102 | Q11: =raw!Q39 -> 3024.5102 | R11: =raw!R39 -> 3024.5102 | S11: =raw!S39 -> 3024.5102 | T11: =raw!T39 -> 3024.5102 | U11: =raw!U39 -> 3024.5102 | V11: =raw!V39 -> 3024.5102 | ... Y11: =raw!Y39 -> 3024.5102 | Z11: =raw!Z41 -> 0 | AB11: =raw!AB39 -> 3024.5102 | AC11: =raw!AC39 -> 3024.5102 | AD11: =raw!AD39 -> 3024.5102 | AE11: =raw!AE39 -> 3024.5102 | AF11: =raw!AF39 -> 3024.5102 | AG11: =raw!AG39 -> 3024.5102 | AH11: =raw!AH39 -> 3024.5102 | AI11: =raw!AI39 -> 3024.5102 | ... AL11: =raw!AL39 -> 3024.5102 | AM11: =raw!AM41 -> 0 | AO11: =raw!AO41 -> 0 | AP11: =raw!AP41 -> 0 | AQ11: =raw!AQ41 -> 0 | AR11: =raw!AR41 -> 0 | AS11: =raw!AS41 -> 0 | AT11: =raw!AT41 -> 0 | AU11: =raw!AU41 -> 0 | AV11: =raw!AV41 -> 0 | ... AZ11: =raw!AZ41 -> 0
A12: Outstanding shares (m) | B12: 流通在外股票 | C12: =raw!B40 -> 2820.482 | D12: =raw!C40 -> 2820.482 | E12: =raw!D40 -> 2820.482 | F12: =raw!E40 -> 2820.482 | G12: =raw!F40 -> 2820.482 | H12: =raw!G40 -> 2820.482 | I12: =raw!H40 -> 2820.482 | J12: =raw!I40 -> 2820.482 | ... N12: =raw!M40 -> 3024.5102 | O12: =raw!O40 -> 3024.5102 | P12: =raw!P40 -> 3024.5102 | Q12: =raw!Q40 -> 3024.5102 | R12: =raw!R40 -> 3024.5102 | S12: =raw!S40 -> 3024.5102 | T12: =raw!T40 -> 3024.5102 | U12: =raw!U40 -> 3024.5102 | V12: =raw!V40 -> 3024.5102 | ... Z12: =raw!Z40 -> 3024.5102 | AB12: =raw!AB40 -> 3024.5102 | AC12: =raw!AC40 -> 3024.5102 | AD12: =raw!AD40 -> 3024.5102 | AE12: =raw!AE40 -> 3024.5102 | AF12: =raw!AF40 -> 3024.5102 | AG12: =raw!AG40 -> 3024.5102 | AH12: =raw!AH40 -> 3024.5102 | AI12: =raw!AI40 -> 3024.5102 | ... AM12: =raw!AM40 -> 3024.5102 | AO12: =raw!AO40 -> 3024.5102 | AP12: =raw!AP40 -> 3024.5102 | AQ12: =raw!AQ40 -> 3030.6622 | AR12: =raw!AR40 -> 3037.4962 | AS12: =raw!AS40 -> 3046.1222 | AT12: =raw!AT40 -> 0 | AU12: =raw!AU40 -> 0 | AV12: =raw!AV40 -> 0 | ... AZ12: =raw!AZ40 -> 0
L15: Total revenue | M15: 183347.82 | N15: =SUM(C4:N4) -> 183347.82 | X15: Total revenue | Y15: 127308.97 | Z15: =SUM(O4:Z4) -> 199373.91
L16: EBITDA | M16: 35788.729 | N16: =SUM(C5:N5) -> 35788.729 | X16: EBITDA | Y16: 28249.569 | Z16: =SUM(O5:Z5) -> 42520.089
L17: Operating income | M17: 17544.704 | N17: =SUM(C6:N6) -> 17544.704 | X17: Operating income | Y17: 13095.778 | Z17: =SUM(O6:Z6) -> 20250.476
L18: Pre-tax income | M18: 17471.364 | N18: =SUM(C9:N9) -> 17471.364 | X18: Pre-tax income | Y18: 12952.805 | Z18: =SUM(O9:Z9) -> 19532.04
L19: Pre-tax income margin | M19: 0.09529082 | N19: =SUM(C10:N10)/12 -> 0.095929162 | X19: Pre-tax income margin | Y19: 0.10174307 | Z19: =SUM(O10:Z10)/12 -> 0.098677723
L20: Net income | M20: 12274.109 | N20: =SUM(C7:N7) -> 12274.109 | X20: Net income | Y20: 9190.5808 | Z20: =SUM(O7:Z7) -> 13816.716
L21: EPS (NT$) | M21: 4.33 | X21: EPS (NT$) | Y21: 3.04
L22: Cumulative weighted-average outstanding shares (m) | M22: 2837.8104 | N22: =N11 -> 2837.8104 | X22: Cumulative weighted-average outstanding shares (m) | Y22: 3024.5102 | Z22: =Z11 -> 0
L23: Outstanding shares (m) | M23: 3024.5102 | N23: =N12 -> 3024.5102 | X23: Outstanding shares (m) | Y23: 3024.5102 | Z23: =Z12 -> 3024.5102
L24: YoY Change | X24: YoY Change
L25: Total revenue | M25: 0.06469987 | X25: Total revenue | Y25: 0.10321505
L26: EBITDA | M26: 0.040963266 | X26: EBITDA | Y26: 0.20188597
L27: Operating income | M27: 0.038594378 | X27: Operating income | Y27: 0.11759732
L28: Pre-tax income | M28: 0.07906263 | X28: Pre-tax income | Y28: 0.15112798
L29: Net income | M29: 0.11324227 | X29: Net income | Y29: 0.17674028
L30: EPS | M30: 0.10741688 | X30: EPS | Y30: 0.097472924

Sheet 大表
C2: 2023 | O2: 2024 | AB2: 2025 | AO2: 2026
C3: 1月 | D3: 2月 | E3: 3月 | F3: 4月 | G3: 5月 | H3: 6月 | I3: 7月 | J3: 8月 | K3: 9月 | L3: 10月 | M3: 11月 | N3: 12月 | O3: 1月 | P3: 2月 | Q3: 3月 | R3: 4月 | S3: 5月 | T3: 6月 | U3: 7月 | V3: 8月 | W3: 9月 | X3: 10月 | Y3: 11月 | Z3: 12月 | AB3: 1月 | AC3: 2月 | AD3: 3月 | AE3: 4月 | AF3: 5月 | AG3: 6月 | AH3: 7月 | AI3: 8月 | AJ3: 9月 | AK3: 10月 | AL3: 11月 | AM3: 12月 | AO3: 1月 | AP3: 2月 | AQ3: 3月 | AR3: 4月 | AS3: 5月 | AT3: 6月 | AU3: 7月 | AV3: 8月 | AW3: 9月 | AX3: 10月 | AY3: 11月 | AZ3: 12月
A4: Total revenue | B4: 合併營收 | C4: =raw!B32 -> 14814.979 | D4: =raw!C32 -> 13735.483 | E4: =raw!D32 -> 14464.876 | F4: =raw!E32 -> 13685.917 | G4: =raw!F32 -> 14776.841 | H4: =raw!G32 -> 15083.561 | I4: =raw!H32 -> 14274.764 | J4: =raw!I32 -> 14561.723 | ... N4: =raw!M32 -> 17080.887 | O4: =raw!O32 -> 16958.579 | P4: =raw!P32 -> 15247.918 | Q4: =raw!Q32 -> 16070.134 | R4: =raw!R32 -> 15042.779 | S4: =raw!S32 -> 16031.947 | T4: =raw!T32 -> 16669.17 | U4: =raw!U32 -> 15470.631 | V4: =raw!V32 -> 15817.81 | ... Z4: =raw!Z32 -> 17156.531 | AB4: =raw!AB32 -> 16461.916 | AC4: =raw!AC32 -> 15528.063 | AD4: =raw!AD32 -> 16177.374 | AE4: =raw!AE32 -> 15393.306 | AF4: =raw!AF32 -> 15823.032 | AG4: =raw!AG32 -> 16254.676 | AH4: =raw!AH32 -> 15092.708 | AI4: =raw!AI32 -> 15468.138 | ... AM4: =raw!AM32 -> 18049.316 | AO4: =raw!AO32 -> 17145.458 | AP4: =raw!AP32 -> 15523.554 | AQ4: =raw!AQ32 -> 17109.29 | AR4: =raw!AR32 -> 15669.305 | AS4: =raw!AS32 -> 16440.683 | AT4: =raw!AT32 -> 0 | AU4: =raw!AU32 -> 0 | AV4: =raw!AV32 -> 0 | ... AZ4: =raw!AZ32 -> 0
A5: YOY | O5: =(O4-C4)/C4 -> 0.1446914 | P5: =(P4-D4)/D4 -> 0.11011153 | Q5: =(Q4-E4)/E4 -> 0.11097628 | R5: =(R4-F4)/F4 -> 0.099142884 | S5: =(S4-G4)/G4 -> 0.08493738 | T5: =(T4-H4)/H4 -> 0.10512168 | U5: =(U4-I4)/I4 -> 0.083774952 | V5: =(V4-J4)/J4 -> 0.086259512 | ... Z5: =(Z4-N4)/N4 -> 0.0044285859 | AB5: =(AB4-O4)/O4 -> -0.029286845 | AC5: =(AC4-P4)/P4 -> 0.01837265 | AD5: =(AD4-Q4)/Q4 -> 0.0066732585 | AE5: =(AE4-R4)/R4 -> 0.023302066 | AF5: =(AF4-S4)/S4 -> -0.013031193 | AG5: =(AG4-T4)/T4 -> -0.024865874 | AH5: =(AH4-U4)/U4 -> -0.024428404 | AI5: =(AI4-V4)/V4 -> -0.022106237 | ... AM5: =(AM4-Z4)/Z4 -> 0.052037639 | AO5: =(AO4-AB4)/AB4 -> 0.041522637 | AP5: =(AP4-AC4)/AC4 -> -0.00029032662 | AQ5: =(AQ4-AD4)/AD4 -> 0.057606123 | AR5: =(AR4-AE4)/AE4 -> 0.017929757 | AS5: =(AS4-AG4)/AG4 -> 0.011443257 | AT5: =(AT4-AH4)/AH4 -> -1 | AU5: =(AU4-AI4)/AI4 -> -1 | AV5: =(AV4-AJ4)/AJ4 -> -1 | AW5: =(AW4-AK4)/AK4 -> -1 | AX5: =(AX4-AL4)/AL4 -> -1 | AY5: =(AY4-AM4)/AM4 -> -1 | AZ5: =(AZ4-AN4)/AN4 -> #DIV/0!
A6: MOM | O6: =(O4-N4)/N4 -> -0.00716048 | P6: =(P4-O4)/O4 -> -0.10087293 | Q6: =(Q4-P4)/P4 -> 0.053923185 | R6: =(R4-Q4)/Q4 -> -0.063929496 | S6: =(S4-R4)/R4 -> 0.065757036 | T6: =(T4-S4)/S4 -> 0.039747059 | U6: =(U4-T4)/T4 -> -0.071901521 | V6: =(V4-U4)/U4 -> 0.022441175 | ... Z6: =(Z4-Y4)/Y4 -> -0.25617758 | AB6: =(AB4-Z4)/Z4 -> -0.040486903 | AC6: =(AC4-AB4)/AB4 -> -0.056728125 | AD6: =(AD4-AC4)/AC4 -> 0.041815378 | AE6: =(AE4-AD4)/AD4 -> -0.048466946 | AF6: =(AF4-AE4)/AE4 -> 0.027916376 | AG6: =(AG4-AF4)/AF4 -> 0.027279516 | AH6: =(AH4-AG4)/AG4 -> -0.071485152 | AI6: =(AI4-AH4)/AH4 -> 0.024874906 | AJ6: =(AJ4-AI4)/AI4 -> 0.020094339 | ... AM6: =(AM4-AL4)/AL4 -> -0.21905439 | AO6: =(AO4-AM4)/AM4 -> -0.050077133 | AP6: =(AP4-AO4)/AO4 -> -0.094596714 | AQ6: =(AQ4-AP4)/AP4 -> 0.10215031 | AR6: =(AR4-AQ4)/AQ4 -> -0.084163954 | AS6: =(AS4-AR4)/AR4 -> 0.049228616 | AT6: =(AT4-AS4)/AS4 -> -1 | AU6: =(AU4-AT4)/AT4 -> #DIV/0! | AV6: =(AV4-AU4)/AU4 -> #DIV/0! | AW6: =(AW4-AV4)/AV4 -> #DIV/0! | ... AZ6: =(AZ4-AY4)/AY4 -> #DIV/0!
A7: EBITDA | B7: 稅息折舊及攤銷前利潤 | C7: =raw!B33 -> 2886.7427 | D7: =raw!C33 -> 2839.2053 | E7: =raw!D33 -> 2956.4667 | F7: =raw!E33 -> 2856.637 | G7: =raw!F33 -> 2954.84 | H7: =raw!G33 -> 3095.2013 | I7: =raw!H33 -> 2961.5653 | J7: =raw!I33 -> 2953.7084 | ... N7: =raw!M33 -> 3519.4083 | O7: =raw!O33 -> 3675.2648 | P7: =raw!P33 -> 3331.6564 | Q7: =raw!Q33 -> 3580.5579 | R7: =raw!R33 -> 3484.0874 | S7: =raw!S33 -> 3490.7401 | T7: =raw!T33 -> 3611.585 | U7: =raw!U33 -> 3513.0108 | V7: =raw!V33 -> 3562.6663 | ... Z7: =raw!Z33 -> 3496.6582 | AB7: =raw!AB33 -> 3590.6773 | AC7: =raw!AC33 -> 3469.5616 | AD7: =raw!AD33 -> 3494.1166 | AE7: =raw!AE33 -> 3437.9751 | AF7: =raw!AF33 -> 3496.4753 | AG7: =raw!AG33 -> 3654.4695 | AH7: =raw!AH33 -> 3575.9519 | AI7: =raw!AI33 -> 3561.4542 | ... AM7: =raw!AM33 -> 3959.8724 | AO7: =raw!AO33 -> 3871.9103 | AP7: =raw!AP33 -> 3584.663 | AQ7: =raw!AQ33 -> 3897.3167 | AR7: =raw!AR33 -> 3787.6145 | AS7: =raw!AS33 -> 3834.421 | AT7: =raw!AT33 -> 0 | AU7: =raw!AU33 -> 0 | AV7: =raw!AV33 -> 0 | ... AZ7: =raw!AZ33 -> 0
A8: YOY | O8: =(O7-C7)/C7 -> 0.27315287 | P8: =(P7-D7)/D7 -> 0.1734468 | Q8: =(Q7-E7)/E7 -> 0.21109362 | R8: =(R7-F7)/F7 -> 0.21964653 | S8: =(S7-G7)/G7 -> 0.18136349 | T8: =(T7-H7)/H7 -> 0.16683363 | U8: =(U7-I7)/I7 -> 0.18620066 | V8: =(V7-J7)/J7 -> 0.20616725 | ... Z8: =(Z7-N7)/N7 -> -0.0064641948 | AB8: =(AB7-P7)/P7 -> 0.077745404 | AC8: =(AC7-Q7)/Q7 -> -0.030999741 | AD8: =(AD7-R7)/R7 -> 0.0028785841 | AE8: =(AE7-S7)/S7 -> -0.015115712 | AF8: =(AF7-T7)/T7 -> -0.031872356 | AG8: =(AG7-U7)/U7 -> 0.040267095 | AH8: =(AH7-V7)/V7 -> 0.0037291076 | AI8: =(AI7-W7)/W7 -> 0.033446557 | ... AM8: =(AM7-AA7)/AA7 -> #DIV/0! | AO8: =(AO7-AC7)/AC7 -> 0.11596529 | AP8: =(AP7-AD7)/AD7 -> 0.025913957 | AQ8: =(AQ7-AE7)/AE7 -> 0.1336082 | AR8: =(AR7-AF7)/AF7 -> 0.083266491 | AS8: =(AS7-AG7)/AG7 -> 0.049241493 | AT8: =(AT7-AH7)/AH7 -> -1 | AU8: =(AU7-AI7)/AI7 -> -1 | AV8: =(AV7-AJ7)/AJ7 -> -1 | ... AZ8: =(AZ7-AN7)/AN7 -> #DIV/0!
A9: MOM | O9: =(O7-N7)/N7 -> 0.044284863 | P9: =(P7-O7)/O7 -> -0.093492157 | Q9: =(Q7-P7)/P7 -> 0.074708047 | R9: =(R7-Q7)/Q7 -> -0.026942875 | S9: =(S7-R7)/R7 -> 0.0019094497 | T9: =(T7-S7)/S7 -> 0.034618711 | U9: =(U7-T7)/T7 -> -0.027293904 | V9: =(V7-U7)/U7 -> 0.014134764 | ... Z9: =(Z7-Y7)/Y7 -> -0.093040241 | AB9: =(AB7-Z7)/Z7 -> 0.026888299 | AC9: =(AC7-AB7)/AB7 -> -0.033730626 | AD9: =(AD7-AC7)/AC7 -> 0.0070772865 | AE9: =(AE7-AD7)/AD7 -> -0.016067457 | AF9: =(AF7-AE7)/AE7 -> 0.017015894 | AG9: =(AG7-AF7)/AF7 -> 0.045186708 | AH9: =(AH7-AG7)/AG7 -> -0.02148536 | AI9: =(AI7-AH7)/AH7 -> -0.0040542092 | AJ9: =(AJ7-AI7)/AI7 -> -0.019268212 | ... AM9: =(AM7-AL7)/AL7 -> -0.017342951 | AO9: =(AO7-AM7)/AM7 -> -0.022213376 | AP9: =(AP7-AO7)/AO7 -> -0.074187476 | AQ9: =(AQ7-AP7)/AP7 -> 0.087219827 | AR9: =(AR7-AQ7)/AQ7 -> -0.028148136 | AS9: =(AS7-AR7)/AR7 -> 0.012357782 | AT9: =(AT7-AS7)/AS7 -> -1 | AU9: =(AU7-AT7)/AT7 -> #DIV/0! | AV9: =(AV7-AU7)/AU7 -> #DIV/0! | AW9: =(AW7-AV7)/AV7 -> #DIV/0! | ... AZ9: =(AZ7-AY7)/AY7 -> #DIV/0!
A10: Operating income | B10: 營業利益 | C10: =raw!B34 -> 1421.5408 | D10: =raw!C34 -> 1376.0586 | E10: =raw!D34 -> 1491.994 | F10: =raw!E34 -> 1384.1967 | G10: =raw!F34 -> 1480.0763 | H10: =raw!G34 -> 1616.0188 | I10: =raw!H34 -> 1477.8706 | J10: =raw!I34 -> 1470.0406 | ... N10: =raw!M34 -> 1533.0298 | O10: =raw!O34 -> 1658.162 | P10: =raw!P34 -> 1356.9527 | Q10: =raw!Q34 -> 1640.184 | R10: =raw!R34 -> 1588.2351 | S10: =raw!S34 -> 1601.4553 | T10: =raw!T34 -> 1761.2851 | U10: =raw!U34 -> 1691.2153 | V10: =raw!V34 -> 1798.2882 | ... Z10: =raw!Z34 -> 1731.3535 | AB10: =raw!AB34 -> 1781.3637 | AC10: =raw!AC34 -> 1668.8929 | AD10: =raw!AD34 -> 1699.3014 | AE10: =raw!AE34 -> 1630.7075 | AF10: =raw!AF34 -> 1691.6897 | AG10: =raw!AG34 -> 1846.0869 | AH10: =raw!AH34 -> 1733.4937 | AI10: =raw!AI34 -> 1725.4035 | ... AM10: =raw!AM34 -> 2169.0488 | AO10: =raw!AO34 -> 2061.9759 | AP10: =raw!AP34 -> 1776.3403 | AQ10: =raw!AQ34 -> 2094.4303 | AR10: =raw!AR34 -> 1989.422 | AS10: =raw!AS34 -> 2043.5707 | AT10: =raw!AT34 -> 0 | AU10: =raw!AU34 -> 0 | AV10: =raw!AV34 -> 0 | ... AZ10: =raw!AZ34 -> 0
A11: YOY | O11: =(O10-C10)/C10 -> 0.1664541 | P11: =(P10-D10)/D10 -> -0.013884477 | Q11: =(Q10-E10)/E10 -> 0.099323504 | R11: =(R10-F10)/F10 -> 0.14740561 | S11: =(S10-G10)/G10 -> 0.082008598 | T11: =(T10-H10)/H10 -> 0.089891505 | U11: =(U10-I10)/I10 -> 0.14435953 | V11: =(V10-J10)/J10 -> 0.2232915 | ... Z11: =(Z10-N10)/N10 -> 0.12936709 | AB11: =(AB10-P10)/P10 -> 0.31276764 | AC11: =(AC10-Q10)/Q10 -> 0.017503411 | AD11: =(AD10-R10)/R10 -> 0.069930684 | AE11: =(AE10-S10)/S10 -> 0.018266012 | AF11: =(AF10-T10)/T10 -> -0.039514009 | AG11: =(AG10-U10)/U10 -> 0.091574147 | AH11: =(AH10-V10)/V10 -> -0.036031214 | AI11: =(AI10-W10)/W10 -> 0.023125567 | ... AM11: =(AM10-AA10)/AA10 -> #DIV/0! | AO11: =(AO10-AC10)/AC10 -> 0.23553519 | AP11: =(AP10-AD10)/AD10 -> 0.045335587 | AQ11: =(AQ10-AE10)/AE10 -> 0.28436909 | AR11: =(AR10-AF10)/AF10 -> 0.17599698 | AS11: =(AS10-AG10)/AG10 -> 0.10697429 | AT11: =(AT10-AH10)/AH10 -> -1 | AU11: =(AU10-AI10)/AI10 -> -1 | AV11: =(AV10-AJ10)/AJ10 -> -1 | ... AZ11: =(AZ10-AN10)/AN10 -> #DIV/0!
A12: MOM | O12: =(O10-N10)/N10 -> 0.081624106 | P12: =(P10-O10)/O10 -> -0.18165251 | Q12: =(Q10-P10)/P10 -> 0.20872599 | R12: =(R10-Q10)/Q10 -> -0.031672642 | S12: =(S10-R10)/R10 -> 0.0083238349 | T12: =(T10-S10)/S10 -> 0.099802884 | U12: =(U10-T10)/T10 -> -0.039783385 | V12: =(V10-U10)/U10 -> 0.063311246 | ... Z12: =(Z10-Y10)/Y10 -> -0.14800472 | AB12: =(AB10-Z10)/Z10 -> 0.028885031 | AC12: =(AC10-AB10)/AB10 -> -0.063137469 | AD12: =(AD10-AC10)/AC10 -> 0.018220814 | AE12: =(AE10-AD10)/AD10 -> -0.040365974 | AF12: =(AF10-AE10)/AE10 -> 0.037396171 | AG12: =(AG10-AF10)/AF10 -> 0.091268007 | AH12: =(AH10-AG10)/AG10 -> -0.060990173 | AI12: =(AI10-AH10)/AH10 -> -0.0046669688 | AJ12: =(AJ10-AI10)/AI10 -> -0.034940663 | ... AM12: =(AM10-AL10)/AL10 -> -0.027974262 | AO12: =(AO10-AM10)/AM10 -> -0.04936401 | AP12: =(AP10-AO10)/AO10 -> -0.13852519 | AQ12: =(AQ10-AP10)/AP10 -> 0.17907044 | AR12: =(AR10-AQ10)/AQ10 -> -0.050136932 | AS12: =(AS10-AR10)/AR10 -> 0.027218304 | AT12: =(AT10-AS10)/AS10 -> -1 | AU12: =(AU10-AT10)/AT10 -> #DIV/0! | AV12: =(AV10-AU10)/AU10 -> #DIV/0! | AW12: =(AW10-AV10)/AV10 -> #DIV/0! | ... AZ12: =(AZ10-AY10)/AY10 -> #DIV/0!
A13: Pre-tax income | B13: 稅前利潤 | C13: =raw!B35 -> 1299.9049 | D13: =raw!C35 -> 1339.4023 | E13: =raw!D35 -> 1421.376 | F13: =raw!E35 -> 1340.0058 | G13: =raw!F35 -> 1399.1266 | H13: =raw!G35 -> 1605.5319 | I13: =raw!H35 -> 1438.1465 | J13: =raw!I35 -> 1408.7778 | ... N13: =raw!M35 -> 2177.1993 | O13: =raw!O35 -> 1566.2901 | P13: =raw!P35 -> 1259.4209 | Q13: =raw!Q35 -> 1496.0923 | R13: =raw!R35 -> 1490.0255 | S13: =raw!S35 -> 1449.3426 | T13: =raw!T35 -> 1619.3797 | U13: =raw!U35 -> 2472.4766 | V13: =raw!V35 -> 1599.7771 | ... Z13: =raw!Z35 -> 1349.2449 | AB13: =raw!AB35 -> 1640.553 | AC13: =raw!AC35 -> 1560.4297 | AD13: =raw!AD35 -> 1709.8262 | AE13: =raw!AE35 -> 1445.6731 | AF13: =raw!AF35 -> 1413.1855 | AG13: =raw!AG35 -> 1694.8403 | AH13: =raw!AH35 -> 1643.4936 | AI13: =raw!AI35 -> 1689.5503 | ... AM13: =raw!AM35 -> 1945.4288 | AO13: =raw!AO35 -> 1964.9515 | AP13: =raw!AP35 -> 1664.0097 | AQ13: =raw!AQ35 -> 2039.9491 | AR13: =raw!AR35 -> 1917.3062 | AS13: =raw!AS35 -> 1968.856 | AT13: =raw!AT35 -> 0 | AU13: =raw!AU35 -> 0 | AV13: =raw!AV35 -> 0 | ... AZ13: =raw!AZ35 -> 0
A14: YOY | O14: =(O13-C13)/C13 -> 0.20492665 | P14: =(P13-D13)/D13 -> -0.059714185 | Q14: =(Q13-E13)/E13 -> 0.052566144 | R14: =(R13-F13)/F13 -> 0.11195453 | S14: =(S13-G13)/G13 -> 0.035891015 | T14: =(T13-H13)/H13 -> 0.0086250654 | U14: =(U13-I13)/I13 -> 0.71921052 | V14: =(V13-J13)/J13 -> 0.13557797 | ... Z14: =(Z13-N13)/N13 -> -0.38028415 | AB14: =(AB13-P13)/P13 -> 0.30262482 | AC14: =(AC13-Q13)/Q13 -> 0.043003695 | AD14: =(AD13-R13)/R13 -> 0.14751473 | AE14: =(AE13-S13)/S13 -> -0.0025319002 | AF14: =(AF13-T13)/T13 -> -0.12732912 | AG14: =(AG13-U13)/U13 -> -0.31451716 | AH14: =(AH13-V13)/V13 -> 0.027326612 | AI14: =(AI13-W13)/W13 -> 0.050956964 | ... AM14: =(AM13-AA13)/AA13 -> #DIV/0! | AO14: =(AO13-AC13)/AC13 -> 0.25923738 | AP14: =(AP13-AD13)/AD13 -> -0.026796021 | AQ14: =(AQ13-AE13)/AE13 -> 0.41107225 | AR14: =(AR13-AF13)/AF13 -> 0.35672654 | AS14: =(AS13-AG13)/AG13 -> 0.16167643 | AT14: =(AT13-AH13)/AH13 -> -1 | AU14: =(AU13-AI13)/AI13 -> -1 | AV14: =(AV13-AJ13)/AJ13 -> -1 | ... AZ14: =(AZ13-AN13)/AN13 -> #DIV/0!
A15: MOM | O15: =(O13-N13)/N13 -> -0.28059406 | P15: =(P13-O13)/O13 -> -0.19592103 | Q15: =(Q13-P13)/P13 -> 0.18792074 | R15: =(R13-Q13)/Q13 -> -0.00405505 | S15: =(S13-R13)/R13 -> -0.027303474 | T15: =(T13-S13)/S13 -> 0.1173201 | U15: =(U13-T13)/T13 -> 0.52680475 | V15: =(V13-U13)/U13 -> -0.35296573 | ... Z15: =(Z13-Y13)/Y13 -> -0.32017289 | AB15: =(AB13-Z13)/Z13 -> 0.21590451 | AC15: =(AC13-AB13)/AB13 -> -0.048839156 | AD15: =(AD13-AC13)/AC13 -> 0.095740607 | AE15: =(AE13-AD13)/AD13 -> -0.15449124 | AF15: =(AF13-AE13)/AE13 -> -0.022472286 | AG15: =(AG13-AF13)/AF13 -> 0.19930489 | AH15: =(AH13-AG13)/AG13 -> -0.030295886 | AI15: =(AI13-AH13)/AH13 -> 0.028023701 | AJ15: =(AJ13-AI13)/AI13 -> -0.076744217 | ... AM15: =(AM13-AL13)/AL13 -> -0.080087312 | AO15: =(AO13-AM13)/AM13 -> 0.010035157 | AP15: =(AP13-AO13)/AO13 -> -0.15315481 | AQ15: =(AQ13-AP13)/AP13 -> 0.22592383 | AR15: =(AR13-AQ13)/AQ13 -> -0.060120564 | AS15: =(AS13-AR13)/AR13 -> 0.026886541 | AT15: =(AT13-AS13)/AS13 -> -1 | AU15: =(AU13-AT13)/AT13 -> #DIV/0! | AV15: =(AV13-AU13)/AU13 -> #DIV/0! | AW15: =(AW13-AV13)/AV13 -> #DIV/0! | ... AZ15: =(AZ13-AY13)/AY13 -> #DIV/0!
A16: Pre-tax income margin | B16: 稅前淨利率 | C16: =raw!B36 -> 0.087742609 | D16: =raw!C36 -> 0.097514027 | E16: =raw!D36 -> 0.09826396 | F16: =raw!E36 -> 0.097911289 | G16: =raw!F36 -> 0.094683741 | H16: =raw!G36 -> 0.1064425 | I16: =raw!H36 -> 0.10074748 | J16: =raw!I36 -> 0.096745269 | ... N16: =raw!M36 -> 0.12746407 | O16: =raw!O36 -> 0.092359747 | P16: =raw!P36 -> 0.082596257 | Q16: =raw!Q36 -> 0.093097683 | R16: =raw!R36 -> 0.099052546 | S16: =raw!S36 -> 0.090403407 | T16: =raw!T36 -> 0.097148189 | U16: =raw!U36 -> 0.15981743 | V16: =raw!V36 -> 0.10113771 | ... Z16: =raw!Z36 -> 0.078643224 | AB16: =raw!AB36 -> 0.099657473 | AC16: =raw!AC36 -> 0.10049095 | AD16: =raw!AD36 -> 0.10569244 | AE16: =raw!AE36 -> 0.093915694 | AF16: =raw!AF36 -> 0.089311929 | AG16: =raw!AG36 -> 0.10426786 | AH16: =raw!AH36 -> 0.10889322 | AI16: =raw!AI36 -> 0.10922778 | ... AM16: =raw!AM36 -> 0.10778407 | AO16: =raw!AO36 -> 0.11460478 | AP16: =raw!AP36 -> 0.10719257 | AQ16: =raw!AQ36 -> 0.1192305 | AR16: =raw!AR36 -> 0.12236065 | AS16: =raw!AS36 -> 0.11975512 | AT16: =raw!AT36 -> 0 | AU16: =raw!AU36 -> 0 | AV16: =raw!AV36 -> 0 | ... AZ16: =raw!AZ36 -> 0
A17: YOY | O17: =(O16-C16)/C16 -> 0.052621384 | P17: =(P16-D16)/D16 -> -0.15298077 | Q17: =(Q16-E16)/E16 -> -0.052575506 | R17: =(R16-F16)/F16 -> 0.011656035 | S17: =(S16-G16)/G16 -> -0.045206632 | T17: =(T16-H16)/H16 -> -0.087317637 | U17: =(U16-I16)/I16 -> 0.5863169 | V17: =(V16-J16)/J16 -> 0.045402099 | ... Z17: =(Z16-N16)/N16 -> -0.38301652 | AB17: =(AB16-P16)/P16 -> 0.20656162 | AC17: =(AC16-Q16)/Q16 -> 0.07941408 | AD17: =(AD16-R16)/R16 -> 0.067034098 | AE17: =(AE16-S16)/S16 -> 0.038851265 | AF17: =(AF16-T16)/T16 -> -0.080662964 | AG17: =(AG16-U16)/U16 -> -0.34758146 | AH17: =(AH16-V16)/V16 -> 0.076682667 | AI17: =(AI16-W16)/W16 -> 0.081187508 | ... AM17: =(AM16-AA16)/AA16 -> #DIV/0! | AO17: =(AO16-AC16)/AC16 -> 0.14044877 | AP17: =(AP16-AD16)/AD16 -> 0.014193319 | AQ17: =(AQ16-AE16)/AE16 -> 0.26954814 | AR17: =(AR16-AF16)/AF16 -> 0.370037 | AS17: =(AS16-AG16)/AG16 -> 0.14853347 | AT17: =(AT16-AH16)/AH16 -> -1 | AU17: =(AU16-AI16)/AI16 -> -1 | AV17: =(AV16-AJ16)/AJ16 -> -1 | ... AZ17: =(AZ16-AN16)/AN16 -> #DIV/0!
A18: MOM | O18: =(O16-N16)/N16 -> -0.27540561 | P18: =(P16-O16)/O16 -> -0.10571153 | Q18: =(Q16-P16)/P16 -> 0.12714167 | R18: =(R16-Q16)/Q16 -> 0.063963607 | S18: =(S16-R16)/R16 -> -0.087318692 | T18: =(T16-S16)/S16 -> 0.074607608 | U18: =(U16-T16)/T16 -> 0.64508916 | V18: =(V16-U16)/U16 -> -0.36716724 | ... Z18: =(Z16-Y16)/Y16 -> -0.086035729 | AB18: =(AB16-Z16)/Z16 -> 0.26720992 | AC18: =(AC16-AB16)/AB16 -> 0.00836341 | AD18: =(AD16-AC16)/AC16 -> 0.05176083 | AE18: =(AE16-AD16)/AD16 -> -0.11142471 | AF18: =(AF16-AE16)/AE16 -> -0.049020195 | AG18: =(AG16-AF16)/AF16 -> 0.16745722 | AH18: =(AH16-AG16)/AG16 -> 0.044360374 | AI18: =(AI16-AH16)/AH16 -> 0.0030723697 | AJ18: =(AJ16-AI16)/AI16 -> -0.094930981 | ... AM18: =(AM16-AL16)/AL16 -> 0.17794719 | AO18: =(AO16-AM16)/AM16 -> 0.063281232 | AP18: =(AP16-AO16)/AO16 -> -0.064676259 | AQ18: =(AQ16-AP16)/AP16 -> 0.11230185 | AR18: =(AR16-AQ16)/AQ16 -> 0.026252941 | AS18: =(AS16-AR16)/AR16 -> -0.02129381 | AT18: =(AT16-AS16)/AS16 -> -1 | AU18: =(AU16-AT16)/AT16 -> #DIV/0! | AV18: =(AV16-AU16)/AU16 -> #DIV/0! | AW18: =(AW16-AV16)/AV16 -> #DIV/0! | ... AZ18: =(AZ16-AY16)/AY16 -> #DIV/0!
A19: Net income | B19: 稅後淨利 | C19: =raw!B37 -> 844.98642 | D19: =raw!C37 -> 925.57407 | E19: =raw!D37 -> 944.15381 | F19: =raw!E37 -> 954.9249 | G19: =raw!F37 -> 971.7405 | H19: =raw!G37 -> 1108.6137 | I19: =raw!H37 -> 1010.5131 | J19: =raw!I37 -> 1049.6967 | ... N19: =raw!M37 -> 1770.4948 | O19: =raw!O37 -> 1055.3977 | P19: =raw!P37 -> 882.42083 | Q19: =raw!Q37 -> 1030.1014 | R19: =raw!R37 -> 1066.945 | S19: =raw!S37 -> 1031.2977 | T19: =raw!T37 -> 1134.3589 | U19: =raw!U37 -> 1836.7955 | V19: =raw!V37 -> 1153.2637 | ... Z19: =raw!Z37 -> 949.26534 | AB19: =raw!AB37 -> 1162.2662 | AC19: =raw!AC37 -> 1254.8655 | AD19: =raw!AD37 -> 1238.0669 | AE19: =raw!AE37 -> 1043.4317 | AF19: =raw!AF37 -> 1004.826 | AG19: =raw!AG37 -> 1240.9329 | AH19: =raw!AH37 -> 1203.2303 | AI19: =raw!AI37 -> 1262.893 | ... AM19: =raw!AM37 -> 1322.2063 | AO19: =raw!AO37 -> 1406.2327 | AP19: =raw!AP37 -> 1240.8602 | AQ19: =raw!AQ37 -> 1499.2274 | AR19: =raw!AR37 -> 1425.7521 | AS19: =raw!AS37 -> 1516.3126 | AT19: =raw!AT37 -> 0 | AU19: =raw!AU37 -> 0 | AV19: =raw!AV37 -> 0 | ... AZ19: =raw!AZ37 -> 0
A20: YOY | O20: =(O19-C19)/C19 -> 0.24901144 | P20: =(P19-D19)/D19 -> -0.046623214 | Q20: =(Q19-E19)/E19 -> 0.091031384 | R20: =(R19-F19)/F19 -> 0.11730778 | S20: =(S19-G19)/G19 -> 0.061289148 | T20: =(T19-H19)/H19 -> 0.023222861 | U20: =(U19-I19)/I19 -> 0.81768605 | V20: =(V19-J19)/J19 -> 0.09866366 | ... Z20: =(Z19-N19)/N19 -> -0.46384179 | AB20: =(AB19-P19)/P19 -> 0.31713363 | AC20: =(AC19-Q19)/Q19 -> 0.21819601 | AD20: =(AD19-R19)/R19 -> 0.16038488 | AE20: =(AE19-S19)/S19 -> 0.011765828 | AF20: =(AF19-T19)/T19 -> -0.11419044 | AG20: =(AG19-U19)/U19 -> -0.32440337 | AH20: =(AH19-V19)/V19 -> 0.043326267 | AI20: =(AI19-W19)/W19 -> 0.07538302 | ... AM20: =(AM19-AA19)/AA19 -> #DIV/0! | AO20: =(AO19-AC19)/AC19 -> 0.12062429 | AP20: =(AP19-AD19)/AD19 -> 0.0022562134 | AQ20: =(AQ19-AE19)/AE19 -> 0.4368237 | AR20: =(AR19-AF19)/AF19 -> 0.41890451 | AS20: =(AS19-AG19)/AG19 -> 0.22191345 | AT20: =(AT19-AH19)/AH19 -> -1 | AU20: =(AU19-AI19)/AI19 -> -1 | AV20: =(AV19-AJ19)/AJ19 -> -1 | ... AZ20: =(AZ19-AN19)/AN19 -> #DIV/0!
A21: MOM | O21: =(O19-N19)/N19 -> -0.40389675 | P21: =(P19-O19)/O19 -> -0.16389734 | Q21: =(Q19-P19)/P19 -> 0.16735847 | R21: =(R19-Q19)/Q19 -> 0.035766949 | S21: =(S19-R19)/R19 -> -0.033410688 | T21: =(T19-S19)/S19 -> 0.099933593 | U21: =(U19-T19)/T19 -> 0.61923661 | V21: =(V19-U19)/U19 -> -0.37213279 | ... Z21: =(Z19-Y19)/Y19 -> -0.28400047 | AB21: =(AB19-Z19)/Z19 -> 0.22438491 | AC21: =(AC19-AB19)/AB19 -> 0.079671338 | AD21: =(AD19-AC19)/AC19 -> -0.013386767 | AE21: =(AE19-AD19)/AD19 -> -0.15720891 | AF21: =(AF19-AE19)/AE19 -> -0.036998817 | AG21: =(AG19-AF19)/AF19 -> 0.23497291 | AH21: =(AH19-AG19)/AG19 -> -0.030382457 | AI21: =(AI19-AH19)/AH19 -> 0.049585448 | AJ21: =(AJ19-AI19)/AI19 -> -0.093686263 | ... AM21: =(AM19-AL19)/AL19 -> -0.070686883 | AO21: =(AO19-AM19)/AM19 -> 0.063550189 | AP21: =(AP19-AO19)/AO19 -> -0.11759967 | AQ21: =(AQ19-AP19)/AP19 -> 0.20821622 | AR21: =(AR19-AQ19)/AQ19 -> -0.04900878 | AS21: =(AS19-AR19)/AR19 -> 0.063517661 | AT21: =(AT19-AS19)/AS19 -> -1 | AU21: =(AU19-AT19)/AT19 -> #DIV/0! | AV21: =(AV19-AU19)/AU19 -> #DIV/0! | AW21: =(AW19-AV19)/AV19 -> #DIV/0! | ... AZ21: =(AZ19-AY19)/AY19 -> #DIV/0!
A22: EPS (NT$) | B22: EPS (NT$) | C22: =raw!B38 -> 0 | D22: =raw!C38 -> 0 | E22: =raw!D38 -> 0 | F22: =raw!E38 -> 0 | G22: =raw!F38 -> 0 | H22: =raw!G38 -> 0 | I22: =raw!H38 -> 0 | J22: =raw!I38 -> 0 | ... N22: =raw!M38 -> 0 | O22: =raw!O38 -> 0 | P22: =raw!P38 -> 0 | Q22: =raw!Q38 -> 0 | R22: =raw!R38 -> 0 | S22: =raw!S38 -> 0 | T22: =raw!T38 -> 0.37 | U22: =raw!U38 -> 0.61 | V22: =raw!V38 -> 0.38 | W22: 0.39 | X22: =raw!X38 -> 0 | Y22: =raw!Y38 -> 0 | Z22: =raw!Z38 -> 0 | AB22: =raw!AB38 -> 0.38 | AC22: =raw!AC38 -> 0.42 | AD22: =raw!AD38 -> 0.41 | AE22: =raw!AE38 -> 0.34 | AF22: =raw!AF38 -> 0.34 | AG22: =raw!AG38 -> 0.41 | AH22: =raw!AH38 -> 0.39 | AI22: =raw!AI38 -> 0.42 | ... AM22: =raw!AM38 -> 0.43 | AO22: =raw!AO38 -> 0.46 | AP22: =raw!AP38 -> 0.42 | AQ22: =raw!AQ38 -> 0.49 | AR22: =raw!AR38 -> 0.47 | AS22: =raw!AS38 -> 0.5 | AT22: =raw!AT38 -> 0 | AU22: =raw!AU38 -> 0 | AV22: =raw!AV38 -> 0 | ... AZ22: =raw!AZ38 -> 0
A23: YOY
A24: MOM
A25: Cumulative weighted-average outstanding shares (m) | B25: Cumulative weighted-average outstanding shares (m) | C25: =raw!B39 -> 2820.482 | D25: =raw!C39 -> 2820.482 | E25: =raw!D39 -> 2820.482 | F25: =raw!E39 -> 2820.482 | G25: =raw!F39 -> 2820.482 | H25: =raw!G39 -> 2820.482 | I25: =raw!H39 -> 2820.482 | J25: =raw!I39 -> 2820.482 | ... N25: =raw!M39 -> 2837.8104 | O25: =raw!O39 -> 3024.5102 | P25: =raw!P39 -> 3024.5102 | Q25: =raw!Q39 -> 3024.5102 | R25: =raw!R39 -> 3024.5102 | S25: =raw!S39 -> 3024.5102 | T25: =raw!T39 -> 3024.5102 | U25: =raw!U39 -> 3024.5102 | V25: =raw!V39 -> 3024.5102 | ... Y25: =raw!Y39 -> 3024.5102 | Z25: =raw!Z41 -> 0 | AB25: =raw!AB39 -> 3024.5102 | AC25: =raw!AC39 -> 3024.5102 | AD25: =raw!AD39 -> 3024.5102 | AE25: =raw!AE39 -> 3024.5102 | AF25: =raw!AF39 -> 3024.5102 | AG25: =raw!AG39 -> 3024.5102 | AH25: =raw!AH39 -> 3024.5102 | AI25: =raw!AI39 -> 3024.5102 | ... AL25: =raw!AL39 -> 3024.5102 | AM25: =raw!AM41 -> 0 | AO25: =raw!AO39 -> 3024.5102 | AP25: =raw!AP39 -> 3024.5102 | AQ25: =raw!AQ39 -> 3025.0376 | AR25: =raw!AR39 -> 3027.3349 | AS25: =raw!AS39 -> 3030.2207 | AT25: =raw!AT39 -> 0 | AU25: =raw!AU39 -> 0 | AV25: =raw!AV39 -> 0 | ... AY25: =raw!AY39 -> 0 | AZ25: =raw!AZ41 -> 0
A26: YOY | O26: =(O25-C25)/C25 -> 0.072338064 | P26: =(P25-D25)/D25 -> 0.072338064 | Q26: =(Q25-E25)/E25 -> 0.072338064 | R26: =(R25-F25)/F25 -> 0.072338064 | S26: =(S25-G25)/G25 -> 0.072338064 | T26: =(T25-H25)/H25 -> 0.072338064 | U26: =(U25-I25)/I25 -> 0.072338064 | V26: =(V25-J25)/J25 -> 0.072338064 | ... Z26: =(Z25-N25)/N25 -> -1 | AB26: =(AB25-P25)/P25 -> 0 | AC26: =(AC25-Q25)/Q25 -> 0 | AD26: =(AD25-R25)/R25 -> 0 | AE26: =(AE25-S25)/S25 -> 0 | AF26: =(AF25-T25)/T25 -> 0 | AG26: =(AG25-U25)/U25 -> 0 | AH26: =(AH25-V25)/V25 -> 0 | AI26: =(AI25-W25)/W25 -> 0 | ... AM26: =(AM25-AA25)/AA25 -> #DIV/0! | AO26: =(AO25-AC25)/AC25 -> 0 | AP26: =(AP25-AD25)/AD25 -> 0 | AQ26: =(AQ25-AE25)/AE25 -> 0.0001743717 | AR26: =(AR25-AF25)/AF25 -> 0.00093394957 | AS26: =(AS25-AG25)/AG25 -> 0.0018880664 | AT26: =(AT25-AH25)/AH25 -> -1 | AU26: =(AU25-AI25)/AI25 -> -1 | AV26: =(AV25-AJ25)/AJ25 -> -1 | ... AZ26: =(AZ25-AN25)/AN25 -> #DIV/0!
A27: MOM | O27: =(O25-N25)/N25 -> 0.065790084 | P27: =(P25-O25)/O25 -> 0 | Q27: =(Q25-P25)/P25 -> 0 | R27: =(R25-Q25)/Q25 -> 0 | S27: =(S25-R25)/R25 -> 0 | T27: =(T25-S25)/S25 -> 0 | U27: =(U25-T25)/T25 -> 0 | V27: =(V25-U25)/U25 -> 0 | ... Z27: =(Z25-Y25)/Y25 -> -1 | AB27: =(AB25-AA25)/AA25 -> #DIV/0! | AC27: =(AC25-AB25)/AB25 -> 0 | AD27: =(AD25-AC25)/AC25 -> 0 | AE27: =(AE25-AD25)/AD25 -> 0 | AF27: =(AF25-AE25)/AE25 -> 0 | AG27: =(AG25-AF25)/AF25 -> 0 | AH27: =(AH25-AG25)/AG25 -> 0 | AI27: =(AI25-AH25)/AH25 -> 0 | ... AM27: =(AM25-AL25)/AL25 -> -1 | AO27: =(AO25-AN25)/AN25 -> #DIV/0! | AP27: =(AP25-AO25)/AO25 -> 0 | AQ27: =(AQ25-AP25)/AP25 -> 0.0001743717 | AR27: =(AR25-AQ25)/AQ25 -> 0.00075944544 | AS27: =(AS25-AR25)/AR25 -> 0.00095322653 | AT27: =(AT25-AS25)/AS25 -> -1 | AU27: =(AU25-AT25)/AT25 -> #DIV/0! | AV27: =(AV25-AU25)/AU25 -> #DIV/0! | ... AZ27: =(AZ25-AY25)/AY25 -> #DIV/0!
A28: Outstanding shares (m) | B28: 流通在外股票 | C28: =raw!B40 -> 2820.482 | D28: =raw!C40 -> 2820.482 | E28: =raw!D40 -> 2820.482 | F28: =raw!E40 -> 2820.482 | G28: =raw!F40 -> 2820.482 | H28: =raw!G40 -> 2820.482 | I28: =raw!H40 -> 2820.482 | J28: =raw!I40 -> 2820.482 | ... N28: =raw!M40 -> 3024.5102 | O28: =raw!O40 -> 3024.5102 | P28: =raw!P40 -> 3024.5102 | Q28: =raw!Q40 -> 3024.5102 | R28: =raw!R40 -> 3024.5102 | S28: =raw!S40 -> 3024.5102 | T28: =raw!T40 -> 3024.5102 | U28: =raw!U40 -> 3024.5102 | V28: =raw!V40 -> 3024.5102 | ... Z28: =raw!Z40 -> 3024.5102 | AB28: =raw!AB40 -> 3024.5102 | AC28: =raw!AC40 -> 3024.5102 | AD28: =raw!AD40 -> 3024.5102 | AE28: =raw!AE40 -> 3024.5102 | AF28: =raw!AF40 -> 3024.5102 | AG28: =raw!AG40 -> 3024.5102 | AH28: =raw!AH40 -> 3024.5102 | AI28: =raw!AI40 -> 3024.5102 | ... AM28: =raw!AM40 -> 3024.5102 | AO28: =raw!AO40 -> 3024.5102 | AP28: =raw!AP40 -> 3024.5102 | AQ28: =raw!AQ40 -> 3030.6622 | AR28: =raw!AR40 -> 3037.4962 | AS28: =raw!AS40 -> 3046.1222 | AT28: =raw!AT40 -> 0 | AU28: =raw!AU40 -> 0 | AV28: =raw!AV40 -> 0 | ... AZ28: =raw!AZ40 -> 0
A29: YOY | O29: =(O28-C28)/C28 -> 0.072338064 | P29: =(P28-D28)/D28 -> 0.072338064 | Q29: =(Q28-E28)/E28 -> 0.072338064 | R29: =(R28-F28)/F28 -> 0.072338064 | S29: =(S28-G28)/G28 -> 0.072338064 | T29: =(T28-H28)/H28 -> 0.072338064 | U29: =(U28-I28)/I28 -> 0.072338064 | V29: =(V28-J28)/J28 -> 0.072338064 | ... Z29: =(Z28-N28)/N28 -> 0 | AB29: =(AB28-P28)/P28 -> 0 | AC29: =(AC28-Q28)/Q28 -> 0 | AD29: =(AD28-R28)/R28 -> 0 | AE29: =(AE28-S28)/S28 -> 0 | AF29: =(AF28-T28)/T28 -> 0 | AG29: =(AG28-U28)/U28 -> 0 | AH29: =(AH28-V28)/V28 -> 0 | AI29: =(AI28-W28)/W28 -> 0 | ... AM29: =(AM28-AA28)/AA28 -> #DIV/0! | AO29: =(AO28-AC28)/AC28 -> 0 | AP29: =(AP28-AD28)/AD28 -> 0 | AQ29: =(AQ28-AE28)/AE28 -> 0.0020340483 | AR29: =(AR28-AF28)/AF28 -> 0.0042935878 | AS29: =(AS28-AG28)/AG28 -> 0.0071456198 | AT29: =(AT28-AH28)/AH28 -> -1 | AU29: =(AU28-AI28)/AI28 -> -1 | AV29: =(AV28-AJ28)/AJ28 -> -1 | ... AZ29: =(AZ28-AN28)/AN28 -> #DIV/0!
A30: MOM | O30: =(O28-N28)/N28 -> 0 | P30: =(P28-O28)/O28 -> 0 | Q30: =(Q28-P28)/P28 -> 0 | R30: =(R28-Q28)/Q28 -> 0 | S30: =(S28-R28)/R28 -> 0 | T30: =(T28-S28)/S28 -> 0 | U30: =(U28-T28)/T28 -> 0 | V30: =(V28-U28)/U28 -> 0 | ... Z30: =(Z28-Y28)/Y28 -> 0 | AB30: =(AB28-AA28)/AA28 -> #DIV/0! | AC30: =(AC28-AB28)/AB28 -> 0 | AD30: =(AD28-AC28)/AC28 -> 0 | AE30: =(AE28-AD28)/AD28 -> 0 | AF30: =(AF28-AE28)/AE28 -> 0 | AG30: =(AG28-AF28)/AF28 -> 0 | AH30: =(AH28-AG28)/AG28 -> 0 | AI30: =(AI28-AH28)/AH28 -> 0 | ... AM30: =(AM28-AL28)/AL28 -> 0 | AO30: =(AO28-AN28)/AN28 -> #DIV/0! | AP30: =(AP28-AO28)/AO28 -> 0 | AQ30: =(AQ28-AP28)/AP28 -> 0.0020340483 | AR30: =(AR28-AQ28)/AQ28 -> 0.0022549527 | AS30: =(AS28-AR28)/AR28 -> 0.0028398389 | AT30: =(AT28-AS28)/AS28 -> -1 | AU30: =(AU28-AT28)/AT28 -> #DIV/0! | AV30: =(AV28-AU28)/AU28 -> #DIV/0! | ... AZ30: =(AZ28-AY28)/AY28 -> #DIV/0!
L33: Total revenue | M33: 183347.82 | N33: =SUM(C4:N4) -> 183347.82 | X33: Total revenue | Y33: 127308.97 | Z33: =SUM(O4:Z4) -> 199373.91 | AK33: Total revenue | AL33: 127308.97 | AM33: =SUM(AB4:AM4) -> 198764.58
L34: EBITDA | M34: 35788.729 | N34: =SUM(C7:N7) -> 35788.729 | X34: EBITDA | Y34: 28249.569 | Z34: =SUM(O7:Z7) -> 42520.089 | AK34: EBITDA | AL34: 28249.569 | AM34: =SUM(AB7:AM7) -> 43170.701
L35: Operating income | M35: 17544.704 | N35: =SUM(C10:N10) -> 17544.704 | X35: Operating income | Y35: 13095.778 | Z35: =SUM(O10:Z10) -> 20250.476 | AK35: Operating income | AL35: 13095.778 | AM35: =SUM(AB10:AM10) -> 21450.084
L36: Pre-tax income | M36: 17471.364 | N36: =SUM(C13:N13) -> 17471.364 | X36: Pre-tax income | Y36: 12952.805 | Z36: =SUM(O13:Z13) -> 19532.04 | AK36: Pre-tax income | AL36: 12952.805 | AM36: =SUM(AB13:AM13) -> 19942.852
L37: Pre-tax income margin | M37: 0.09529082 | N37: =SUM(C16:N16)/12 -> 0.095929162 | X37: Pre-tax income margin | Y37: 0.10174307 | Z37: =SUM(O16:Z16)/12 -> 0.098677723 | AK37: Pre-tax income margin | AL37: 0.10174307 | AM37: =SUM(AB16:AM16)/12 -> 0.10060116
L38: Net income | M38: 12274.109 | N38: =SUM(C19:N19) -> 12274.109 | X38: Net income | Y38: 9190.5808 | Z38: =SUM(O19:Z19) -> 13816.716 | AK38: Net income | AL38: 9190.5808 | AM38: =SUM(AB19:AM19) -> 14437.394
L39: EPS (NT$) | M39: 4.33 | X39: EPS (NT$) | Y39: 3.04 | AK39: EPS (NT$) | AL39: 3.04
L40: Cumulative weighted-average outstanding shares (m) | M40: 2837.8104 | N40: =N25 -> 2837.8104 | X40: Cumulative weighted-average outstanding shares (m) | Y40: 3024.5102 | Z40: =Z25 -> 0 | AK40: Cumulative weighted-average outstanding shares (m) | AL40: 3024.5102 | AM40: =AM25 -> 0
L41: Outstanding shares (m) | M41: 3024.5102 | N41: =N28 -> 3024.5102 | X41: Outstanding shares (m) | Y41: 3024.5102 | Z41: =Z28 -> 3024.5102 | AK41: Outstanding shares (m) | AL41: 3024.5102 | AM41: =AM28 -> 3024.5102
L42: YoY Change | X42: YoY Change | AK42: YoY Change
L43: Total revenue | M43: 0.06469987 | X43: Total revenue | Y43: 0.10321505 | AK43: Total revenue | AL43: 0.10321505
...

Sheet raw
A1: IFRS Basis | B1: 44927 | C1: 44958 | D1: 44986 | E1: 45017 | F1: 45047 | G1: 45078 | H1: 45108 | I1: 45139 | J1: 45170 | K1: 45200 | L1: 45231 | M1: 45261 | N1: 2023 | O1: 45292 | P1: 45323 | Q1: 45352 | R1: 45383 | S1: 45413 | T1: 45444 | U1: 45474 | V1: 45505 | W1: 45536 | X1: 45566 | Y1: 45597 | Z1: 45627 | AA1: YTD | AB1: 45658 | AC1: 45689 | AD1: 45717 | AE1: 45748 | AF1: 45778 | AG1: 45809 | AH1: 45839 | AI1: 45870 | AJ1: 45901 | AK1: 45931 | AL1: 45962 | AM1: 45992 | AN1: YTD | AO1: 46023 | AP1: 46054 | AQ1: 46082 | AR1: 46113 | AS1: 46143 | AT1: 46174 | AU1: 46204 | AV1: 46235 | AW1: 46266 | AX1: 46296 | AY1: 46327 | AZ1: 46357
A3: Divisional data
A4: Telecom revenues (NT$m) | B4: 5909.0435 | C4: 5606.6057 | D4: 5713.7152 | E4: 5417.7511 | F4: 5486.6438 | G4: 5505.8398 | H4: 5510.0228 | I4: 5628.728 | J4: 6083.6738 | K4: 6851.4304 | L4: 6651.3329 | M4: 7124.2532 | N4: 71489.04 | O4: 7078.8277 | P4: 6822.4953 | Q4: 6819.5644 | R4: 6669.4109 | S4: 6846.1664 | T4: 6915.9395 | U4: 6686.7213 | V4: 6841.5294 | W4: 7464.9148 | X4: 7776.8359 | Y4: 7586.2265 | Z4: 7343.7404 | AA4: 84852.361 | AB4: 7250.5145 | AC4: 7128.2285 | AD4: 7134.7561 | AE4: 7125.2227 | AF4: 7062.6049 | AG4: 6925.5655 | AH4: 6784.3559 | AI4: 6808.4452 | AJ4: 7774.577 | AK4: 7934.9461 | AL4: 8618.5553 | AM4: 8822.9764 | AN4: 89387.891 | AO4: 7715.2718 | AP4: 7208.0924 | AQ4: 7835.2459 | AR4: 7220.239 | AS4: 7278.9858
A5: Service revenue | B5: 4033.6884 | C5: 4026.4127 | D5: 4039.3745 | E5: 4059.4071 | F5: 4099.3666 | G5: 4127.9582 | H5: 4165.3973 | I5: 4185.0509 | J5: 4141.6915 | K5: 4216.1976 | L5: 4234.3114 | M5: 5071.1524 | N5: 50400.009 | O5: 5051.9108 | P5: 4987.1678 | Q5: 5045.8414 | R5: 5024.9086 | S5: 5010.0536 | T5: 5153.1177 | U5: 5058.8389 | V5: 5196.9004 | W5: 5073.3232 | X5: 5105.0428 | Y5: 5128.3931 | Z5: 5110.4611 | AA5: 60945.762 | AB5: 5134.1507 | AC5: 5070.6765 | AD5: 5102.5063 | AE5: 5105.2738 | AF5: 5117.2435 | AG5: 5130.7358 | AH5: 5195.2002 | AI5: 5214.3018 | AJ5: 5287.099 | AK5: 5301.6602 | AL5: 5752.588 | AM5: 6509.5899 | AN5: 63938.169 | AO5: 5348.1958 | AP5: 5217.3703 | AQ5: 5691.2274 | AR5: 5324.6435 | AS5: 5290.0887
A6: Device sales revenue | B6: 1875.3552 | C6: 1580.1931 | D6: 1674.3407 | E6: 1358.344 | F6: 1387.2773 | G6: 1377.8816 | H6: 1344.6255 | I6: 1443.6771 | J6: 1941.9823 | K6: 2635.2328 | L6: 2417.0215 | M6: 2053.1007 | N6: 21089.032 | O6: 2026.9169 | P6: 1835.3275 | Q6: 1773.7231 | R6: 1644.5023 | S6: 1836.1128 | T6: 1762.8218 | U6: 1627.8824 | V6: 1644.6289 | W6: 2391.5916 | X6: 2671.7931 | Y6: 2457.8334 | Z6: 2233.2793 | AA6: 23906.6 | AB6: 2116.3638 | AC6: 2057.552 | AD6: 2032.2498 | AE6: 2019.9489 | AF6: 1945.3614 | AG6: 1794.8297 | AH6: 1589.1557 | AI6: 1594.1434 | AJ6: 2487.4779 | AK6: 2633.286 | AL6: 2865.9673 | AM6: 2313.3865 | AN6: 25449.722 | AO6: 2367.076 | AP6: 1990.7221 | AQ6: 2144.0185 | AR6: 1895.5955 | AS6: 1988.8972
A7: EBITDA7 | B7: 2116.8799 | C7: 2158.5071 | D7: 2173.2471 | E7: 2223.3597 | F7: 2209.8266 | G7: 2315.0637 | H7: 2267.2101 | I7: 2243.5114 | J7: 2182.2758 | K7: 2155.9186 | L7: 2168.5977 | M7: 2571.868 | N7: 26786.266 | O7: 2728.1811 | P7: 2656.6343 | Q7: 2796.1984 | R7: 2766.6314 | S7: 2745.5584 | T7: 2837.925 | U7: 2781.2481 | V7: 2864.3191 | W7: 2762.9019 | X7: 2721.7558 | Y7: 2775.2213 | Z7: 2533.092 | AA7: 32969.656 | AB7: 2891.8964 | AC7: 2880.6402 | AD7: 2819.3553 | AE7: 2827.5369 | AF7: 2830.9035 | AG7: 2950.5479 | AH7: 2961.1878 | AI7: 2948.4815 | AJ7: 2883.6239 | AK7: 2819.4368 | AL7: 3019.7148 | AM7: 3142.8128 | AN7: 34993.281 | AO7: 3145.2297 | AP7: 3017.8951 | AQ7: 3217.3235 | AR7: 3175.2866 | AS7: 3159.5825
A8: Cable revenues (NT$m) | B8: 516.78253 | C8: 521.47907 | D8: 520.7061 | E8: 521.99365 | F8: 522.10625 | G8: 527.30881 | H8: 523.47828 | I8: 523.58063 | J8: 516.36092 | K8: 526.90148 | L8: 527.00834 | M8: 515.7429 | N8: 6263.449 | O8: 490.1911 | P8: 488.97415 | Q8: 489.57149 | R8: 491.93927 | S8: 491.18973 | T8: 492.71673 | U8: 494.20393 | V8: 495.08134 | W8: 494.9508 | X8: 476.55729 | Y8: 491.72281 | Z8: 497.09423 | AA8: 5894.1929 | AB8: 489.79641 | AC8: 491.34077 | AD8: 491.63812 | AE8: 489.35918 | AF8: 519.90459 | AG8: 489.72482 | AH8: 490.07675 | AI8: 495.73694 | AJ8: 495.16487 | AK8: 491.77642 | AL8: 494.49881 | AM8: 492.67958 | AN8: 5931.6972 | AO8: 568.49107 | AP8: 566.48063 | AQ8: 571.07253 | AR8: 567.90928 | AS8: 569.04378
A9: EBITDA | B9: 246.17153 | C9: 247.59667 | D9: 250.29132 | E9: 249.25848 | F9: 250.85905 | G9: 254.37853 | H9: 248.68989 | I9: 248.15414 | J9: 247.26648 | K9: 247.02872 | L9: 250.16851 | M9: 230.15537 | N9: 2970.0187 | O9: 262.41882 | P9: 260.07224 | Q9: 261.5186 | R9: 263.85811 | S9: 261.96303 | T9: 262.02224 | U9: 265.14987 | V9: 263.15357 | W9: 264.50567 | X9: 264.75531 | Y9: 264.26789 | Z9: 262.13629 | AA9: 3155.8217 | AB9: 261.77867 | AC9: 260.45135 | AD9: 264.50694 | AE9: 263.7162 | AF9: 291.78978 | AG9: 261.11433 | AH9: 262.33156 | AI9: 263.33814 | AJ9: 262.3162 | AK9: 260.16701 | AL9: 264.28389 | AM9: 250.33422 | AN9: 3166.1283 | AO9: 264.46422 | AP9: 264.58126 | AQ9: 262.24277 | AR9: 262.91197 | AS9: 265.43994
A10: momo revenues (NT$m) | B10: 8752.3525 | C10: 7899.1809 | D10: 8468.5062 | E10: 7960.233 | F10: 8976.3335 | G10: 9275.8488 | H10: 8458.7584 | I10: 8619.2507 | J10: 7996.6658 | K10: 7943.6209 | L10: 15158.467 | M10: 9733.7006 | N10: 109242.92 | O10: 9665.4438 | P10: 8188.6344 | Q10: 9023.7904 | R10: 8119.8718 | S10: 8977.6446 | T10: 9559.43 | U10: 8545.5839 | V10: 8762.0695 | W10: 8245.2833 | X10: 8156.0099 | Y10: 15572.54 | Z10: 9747.3329 | AA10: 112563.63 | AB10: 9148.3504 | AC10: 8300.7009 | AD10: 8956.1045 | AE10: 8172.686 | AF10: 8632.9413 | AG10: 9225.2425 | AH10: 8129.8002 | AI10: 8488.0428 | AJ10: 7938.0356 | AK10: 7798.9887 | AL10: 14678.791 | AM10: 9196.2364 | AN10: 108665.92 | AO10: 9322.5656 | AP10: 8129.0414 | AQ10: 9141.8591 | AR10: 8280.8469 | AS10: 8987.0778
A11: Other revenue (NT$m)1 | B11: 46.688 | C11: 49.135239 | D11: 50.715584 | E11: 49.736892 | F11: 49.533895 | G11: 51.486896 | H11: 49.940697 | I11: 54.307706 | J11: 50.945038 | K11: 52.211111 | L11: 53.10676 | M11: 53.087416 | N11: 610.89523 | O11: 48.925722 | P11: 47.907127 | Q11: 52.433787 | R11: 52.000111 | S11: 54.50553 | T11: 53.13248 | U11: 53.479154 | V11: 53.533684 | W11: 54.515851 | X11: 57.854635 | Y11: 57.532145 | Z11: 55.761765 | AA11: 641.58199 | AB11: 51.424905 | AC11: 51.424905 | AD11: 51.424905 | AE11: 55.915397 | AF11: 54.855748 | AG11: 53.601917 | AH11: 53.620473 | AI11: 53.799787 | AJ11: 58.513108 | AK11: 59.37003 | AL11: 63.445799 | AM11: 58.07223 | AN11: 667.97408 | AO11: 57.845456 | AP11: 51.317054 | AQ11: 63.54532 | AR11: 58.759656 | AS11: 54.754513
A13: Subscriber (k)
A14: Mobile | B14: 7468.929 | C14: 7476.772 | D14: 7516.667 | E14: 7534.602 | F14: 7544.399 | G14: 7554.348 | H14: 7583.139 | I14: 7613.789 | J14: 7653.427 | K14: 7683.028 | L14: 7703.674 | M14: 10131.743 | N14: 10131.743 | O14: 10081.195 | P14: 10034.934 | Q14: 10049.41 | R14: 10049.631 | S14: 10051.272 | T14: 10061.487 | U14: 10065.977 | V14: 10065.906 | W14: 10048.009 | X14: 10038.53 | Y14: 10027.068 | Z14: 10005.989 | AA14: 10005.989 | AB14: 10003.574 | AC14: 10026.799 | AD14: 10025.799 | AE14: 10020.158 | AF14: 10008.173 | AG14: 10007.839 | AH14: 9940.317 | AI14: 9902.997 | AJ14: 9817.003 | AK14: 9744.682 | AL14: 9703.184 | AM14: 9632.579 | AN14: 9703.184 | AO14: 9655.695 | AP14: 9681.547 | AQ14: 9693.444 | AR14: 9683.989 | AS14: 9702.885
A15: Postpaid | B15: 6063.566 | C15: 6072.915 | D15: 6106.896 | E15: 6127.406 | F15: 6145.829 | G15: 6161.065 | H15: 6174.613 | I15: 6199.113 | J15: 6240.515 | K15: 6253.954 | L15: 6269.358 | M15: 8420.271 | N15: 8420.271 | O15: 8422.059 | P15: 8446.116 | Q15: 8455.911 | R15: 8461.939 | S15: 8467.777 | T15: 8479.831 | U15: 8490.977 | V15: 8499.133 | W15: 8482.284 | X15: 8484.174 | Y15: 8484.389 | Z15: 8470.172 | AA15: 8470.172 | AB15: 8470.845 | AC15: 8483.63 | AD15: 8484.859 | AE15: 8487.953 | AF15: 8488.455 | AG15: 8512.63 | AH15: 8512.008 | AI15: 8556.697 | AJ15: 8554.533 | AK15: 8547.729 | AL15: 8555.647 | AM15: 8557.655 | AN15: 8555.647 | AO15: 8599.921 | AP15: 8624.149 | AQ15: 8627.331 | AR15: 8625.103 | AS15: 8646.038
A16: Cable
A17: Cable TV | B17: 525.859 | C17: 524.648 | D17: 523.352 | E17: 521.958 | F17: 520.33 | G17: 518.777 | H17: 516.979 | I17: 515.113 | J17: 513.036 | K17: 510.926 | L17: 508.953 | M17: 507.092 | N17: 507.092 | O17: 505.452 | P17: 503.742 | Q17: 501.92 | R17: 500.266 | S17: 498.636 | T17: 497.231 | U17: 495.725 | V17: 494.058 | W17: 492.709 | X17: 491.431 | Y17: 490.172 | Z17: 488.56 | AA17: 488.56 | AB17: 487.555 | AC17: 486.365 | AD17: 485.266 | AE17: 484.042 | AF17: 482.756 | AG17: 481.621 | AH17: 480.586 | AI17: 479.507 | AJ17: 478.444 | AK17: 477.41 | AL17: 476.717 | AM17: 475.691 | AN17: 475.691 | AO17: 474.789 | AP17: 474.095 | AQ17: 473.09 | AR17: 471.946 | AS17: 470.617
A18: Cable broadband2 | B18: 295.153 | C18: 296.117 | D18: 297.106 | E18: 299.289 | F18: 300.269 | G18: 301.267 | H18: 302.058 | I18: 302.952 | J18: 303.757 | K18: 304.184 | L18: 304.862 | M18: 305.494 | N18: 305.494 | O18: 306.315 | P18: 307.06 | Q18: 308.012 | R18: 308.994 | S18: 309.614 | T18: 310.691 | U18: 311.71 | V18: 312.639 | W18: 313.586 | X18: 314.599 | Y18: 315.632 | Z18: 316.491 | AA18: 316.491 | AB18: 317.603 | AC18: 318.617 | AD18: 319.67 | AE18: 320.618 | AF18: 321.711 | AG18: 322.903 | AH18: 323.797 | AI18: 324.723 | AJ18: 326.161 | AK18: 327.064 | AL18: 328.039 | AM18: 328.924 | AN18: 328.924 | AO18: 330.041 | AP18: 330.875 | AQ18: 331.967 | AR18: 332.646 | AS18: 333.198
A20: ARPU (NT$)
A21: Mobile3 | B21: 556.62535 | C21: 557.05742 | D21: 565.2384 | E21: 556.79162 | F21: 562.80829 | G21: 568.50065 | H21: 571.39883 | I21: 570.61288 | J21: 564.41151 | K21: 571.82183 | L21: 571.80731 | M21: 523.43607 | N21: 561.70918 | O21: 529.37802 | P21: 525.8341 | Q21: 531.99118 | R21: 529.76523 | S21: 528.49942 | T21: 535.22051 | U21: 535.48195 | V21: 546.12415 | W21: 537.93216 | X21: 539.95578 | Y21: 545.07564 | Z21: 544.71988 | AA21: 535.8315 | AB21: 543.68282 | AC21: 537.34501 | AD21: 540.91709 | AE21: 542.4049 | AF21: 544.43361 | AG21: 547.69416 | AH21: 554.69102 | AI21: 556.40105 | AJ21: 563.07946 | AK21: 568.61197 | AL21: 577.01488 | AM21: 583.97783 | AN21: 555.02115 | AO21: 584.68971 | AP21: 572.91582 | AQ21: 581.12028 | AR21: 576.87725 | AS21: 579.87525
A22: Postpaid | B22: 661.69725 | C22: 661.63072 | D22: 669.24183 | E22: 659.36308 | F22: 664.60218 | G22: 670.8163 | H22: 674.52218 | I22: 674.13949 | J22: 666.83304 | K22: 675.36659 | L22: 677.01208 | M22: 605.67379 | N22: 663.40821 | O22: 609.77234 | P22: 603.7269 | Q22: 608.22977 | R22: 606.7946 | S22: 603.57715 | T22: 612.25758 | U22: 611.40349 | V22: 623.60788 | W22: 614.78658 | X22: 616.05496 | Y22: 621.78693 | Z22: 619.68482 | AA22: 612.64025 | AB22: 618.29554 | AC22: 613.3137 | AD22: 615.30523 | AE22: 617.53703 | AF22: 618.72847 | AG22: 622.1645 | AH22: 626.05945 | AI22: 623.30288 | AJ22: 626.53924 | AK22: 627.20894 | AL22: 633.40964 | AM22: 635.93483 | AN22: 623.14995 | AO22: 634.46128 | AP22: 622.61732 | AQ22: 630.55417 | AR22: 627.24312 | AS22: 630.04512
A23: 09x postpaid6 | B23: 693.34614 | C23: 694.12062 | D23: 702.8071 | E23: 693.29255 | F23: 699.75406 | G23: 707.97577 | H23: 714.76132 | I23: 717.11682 | J23: 712.25427 | K23: 723.85214 | L23: 726.33427 | M23: 649.14257 | N23: 702.89647 | O23: 654.49523 | P23: 649.37228 | Q23: 655.34504 | R23: 654.01008 | S23: 650.78412 | T23: 660.41832 | U23: 660.04573 | V23: 673.64537 | W23: 664.4715 | X23: 666.1788 | Y23: 672.32868 | Z23: 669.89993 | AA23: 660.9191 | AB23: 668.50677 | AC23: 663.2415 | AD23: 665.36143 | AE23: 667.78841 | AF23: 669.05703 | AG23: 672.96295 | AH23: 677.28383 | AI23: 675.89145 | AJ23: 680.82527 | AK23: 681.4062 | AL23: 688.48383 | AM23: 691.66686 | AN23: 675.20629 | AO23: 691.79208 | AP23: 680.47025 | AQ23: 689.29604 | AR23: 686.06583 | AS23: 689.92553
A24: Cable4 | B24: 803.30207 | C24: 811.38065 | D24: 813.86074 | E24: 817.58749 | F24: 821.20372 | G24: 834.93054 | H24: 826.38782 | I24: 829.82832 | J24: 819.10439 | K24: 838.78709 | L24: 845.15647 | M24: 855.95471 | N24: 826.457 | O24: 870.33807 | P24: 871.05027 | Q24: 877.60498 | R24: 881.39186 | S24: 885.71503 | T24: 892.79694 | U24: 897.35496 | V24: 900.62635 | W24: 901.59462 | X24: 903.05298 | Y24: 902.59941 | Z24: 908.92074 | AA24: 891.08718 | AB24: 910.18509 | AC24: 916.796 | AD24: 918.50571 | AE24: 917.89285 | AF24: 924.33651 | AG24: 924.22265 | AH24: 926.92793 | AI24: 934.58545 | AJ24: 941.15259 | AK24: 934.4578 | AL24: 942.20929 | AM24: 935.97739 | AN24: 927.27077 | AO24: 940.96548 | AP24: 941.06265 | AQ24: 948.85344 | AR24: 943.03034 | AS24: 948.24655
A26: Mobile Churn rate (%) | B26: 0.018884364 | C26: 0.01488883 | D26: 0.015644843 | E26: 0.015487332 | F26: 0.017308972 | G26: 0.01839901 | H26: 0.018545879 | I26: 0.015322176 | J26: 0.016144528 | K26: 0.014750866 | L26: 0.015524314 | M26: 0.026910367 | N26: 0.017317623 | O26: 0.01980108 | P26: 0.020698117 | Q26: 0.016463968 | R26: 0.015473077 | S26: 0.015982267 | T26: 0.015262153 | U26: 0.015307045 | V26: 0.015496216 | W26: 0.016461141 | X26: 0.015530699 | Y26: 0.014778229 | Z26: 0.014521099 | AA26: 0.016314591 | AB26: 0.012938813 | AC26: 0.011268387 | AD26: 0.013956895 | AE26: 0.012837601 | AF26: 0.013412401 | AG26: 0.01467665 | AH26: 0.018785195 | AI26: 0.020260527 | AJ26: 0.020908621 | AK26: 0.019759954 | AL26: 0.017054622 | AM26: 0.019557852 | AN26: 0.016284793 | AO26: 0.013287244 | AP26: 0.0097273437 | AQ26: 0.011891722 | AR26: 0.011738603 | AS26: 0.011493343
A27: Postpaid Churn rate (%) | B27: 0.006636705 | C27: 0.0064629937 | D27: 0.0081191736 | E27: 0.0070464175 | F27: 0.0073211342 | G27: 0.0083200522 | H27: 0.011596606 | I27: 0.0062652107 | J27: 0.0065469803 | K27: 0.0068339039 | L27: 0.0068531392 | M27: 0.016840488 | N27: 0.0082369004 | O27: 0.0070275312 | P27: 0.0064717137 | Q27: 0.0073350966 | R27: 0.0067594878 | S27: 0.0073000634 | T27: 0.0065145477 | U27: 0.0065615026 | V27: 0.0067822986 | W27: 0.0093300812 | X27: 0.007009595 | Y27: 0.0070750835 | Z27: 0.007458406 | AA27: 0.0071354506 | AB27: 0.0058371938 | AC27: 0.0058375149 | AD27: 0.0063346831 | AE27: 0.005769698 | AF27: 0.0060268344 | AG27: 0.0060310268 | AH27: 0.0058000646 | AI27: 0.0058300849 | AJ27: 0.0064981886 | AK27: 0.0065587815 | AL27: 0.0057144274 | AM27: 0.0054792465 | AN27: 0.0059764787 | AO27: 0.0053450441 | AP27: 0.0042758767 | AQ27: 0.0056354585 | AR27: 0.0052572292 | AS27: 0.005119986
A30: Unaudited Consolidated Financials (NT$m) | B30: 44927 | C30: 44958 | D30: 44986 | E30: 45017 | F30: 45047 | G30: 45078 | H30: 45108 | I30: 45139 | J30: 45170 | K30: 45200 | L30: 45231 | M30: 45261 | N30: 2023 | O30: 45292 | P30: 45323 | Q30: 45352 | R30: 45383 | S30: 45413 | T30: 45444 | U30: 45474 | V30: 45505 | W30: 45536 | X30: 45566 | Y30: 45597 | Z30: 45627 | AA30: 2024 | AB30: 45658 | AC30: 45689 | AD30: 45717 | AE30: 45748 | AF30: 45778 | AG30: 45809 | AH30: 45839 | AI30: 45870 | AJ30: 45901 | AK30: 45931 | AL30: 45962 | AM30: 45992 | AN30: 2025 | AO30: 46023 | AP30: 46054 | AQ30: 46082 | AR30: 46113 | AS30: 46143
A32: Total revenue | B32: 14814.979 | C32: 13735.483 | D32: 14464.876 | E32: 13685.917 | F32: 14776.841 | G32: 15083.561 | H32: 14274.764 | I32: 14561.723 | J32: 14350.565 | K32: 14817.542 | L32: 21700.686 | M32: 17080.887 | N32: 183347.82 | O32: 16958.579 | P32: 15247.918 | Q32: 16070.134 | R32: 15042.779 | S32: 16031.947 | T32: 16669.17 | U32: 15470.631 | V32: 15817.81 | W32: 15913.076 | X32: 15929.971 | Y32: 23065.359 | Z32: 17156.531 | AA32: 199373.91 | AB32: 16461.916 | AC32: 15528.063 | AD32: 16177.374 | AE32: 15393.306 | AF32: 15823.032 | AG32: 16254.676 | AH32: 15092.708 | AI32: 15468.138 | AJ32: 15778.96 | AK32: 15624.963 | AL32: 23112.13 | AM32: 18049.316 | AN32: 198764.58 | AO32: 17145.458 | AP32: 15523.554 | AQ32: 17109.29 | AR32: 15669.305 | AS32: 16440.683
A33: EBITDA | B33: 2886.7427 | C33: 2839.2053 | D33: 2956.4667 | E33: 2856.637 | F33: 2954.84 | G33: 3095.2013 | H33: 2961.5653 | I33: 2953.7084 | J33: 2834.8834 | K33: 2830.609 | L33: 3099.4616 | M33: 3519.4083 | N33: 35788.729 | O33: 3675.2648 | P33: 3331.6564 | Q33: 3580.5579 | R33: 3484.0874 | S33: 3490.7401 | T33: 3611.585 | U33: 3513.0108 | V33: 3562.6663 | W33: 3446.191 | X33: 3472.3096 | Y33: 3855.362 | Z33: 3496.6582 | AA33: 42520.089 | AB33: 3590.6773 | AC33: 3469.5616 | AD33: 3494.1166 | AE33: 3437.9751 | AF33: 3496.4753 | AG33: 3654.4695 | AH33: 3575.9519 | AI33: 3561.4542 | AJ33: 3492.8314 | AK33: 3407.5551 | AL33: 4029.7603 | AM33: 3959.8724 | AN33: 43170.701 | AO33: 3871.9103 | AP33: 3584.663 | AQ33: 3897.3167 | AR33: 3787.6145 | AS33: 3834.421
A34: Operating income | B34: 1421.5408 | C34: 1376.0586 | D34: 1491.994 | E34: 1384.1967 | F34: 1480.0763 | G34: 1616.0188 | H34: 1477.8706 | I34: 1470.0406 | J34: 1349.7684 | K34: 1345.4326 | L34: 1598.6765 | M34: 1533.0298 | N34: 17544.704 | O34: 1658.162 | P34: 1356.9527 | Q34: 1640.184 | R34: 1588.2351 | S34: 1601.4553 | T34: 1761.2851 | U34: 1691.2153 | V34: 1798.2882 | W34: 1686.4045 | X34: 1704.8239 | Y34: 2032.1163 | Z34: 1731.3535 | AA34: 20250.476 | AB34: 1781.3637 | AC34: 1668.8929 | AD34: 1699.3014 | AE34: 1630.7075 | AF34: 1691.6897 | AG34: 1846.0869 | AH34: 1733.4937 | AI34: 1725.4035 | AJ34: 1665.1168 | AK34: 1607.5063 | AL34: 2231.4726 | AM34: 2169.0488 | AN34: 21450.084 | AO34: 2061.9759 | AP34: 1776.3403 | AQ34: 2094.4303 | AR34: 1989.422 | AS34: 2043.5707
A35: Pre-tax income | B35: 1299.9049 | C35: 1339.4023 | D35: 1421.376 | E35: 1340.0058 | F35: 1399.1266 | G35: 1605.5319 | H35: 1438.1465 | I35: 1408.7778 | J35: 1286.1522 | K35: 1262.3765 | L35: 1493.3648 | M35: 2177.1993 | N35: 17471.364 | O35: 1566.2901 | P35: 1259.4209 | Q35: 1496.0923 | R35: 1490.0255 | S35: 1449.3426 | T35: 1619.3797 | U35: 2472.4766 | V35: 1599.7771 | W35: 1607.6304 | X35: 1637.6719 | Y35: 1984.6883 | Z35: 1349.2449 | AA35: 19532.04 | AB35: 1640.553 | AC35: 1560.4297 | AD35: 1709.8262 | AE35: 1445.6731 | AF35: 1413.1855 | AG35: 1694.8403 | AH35: 1643.4936 | AI35: 1689.5503 | AJ35: 1559.8871 | AK35: 1525.1875 | AL35: 2114.7972 | AM35: 1945.4288 | AN35: 19942.852 | AO35: 1964.9515 | AP35: 1664.0097 | AQ35: 2039.9491 | AR35: 1917.3062 | AS35: 1968.856
A36: Pre-tax income margin | B36: 0.087742609 | C36: 0.097514027 | D36: 0.09826396 | E36: 0.097911289 | F36: 0.094683741 | G36: 0.1064425 | H36: 0.10074748 | I36: 0.096745269 | J36: 0.0896238 | K36: 0.085194725 | L36: 0.068816479 | M36: 0.12746407 | N36: 0.09529082 | O36: 0.092359747 | P36: 0.082596257 | Q36: 0.093097683 | R36: 0.099052546 | S36: 0.090403407 | T36: 0.097148189 | U36: 0.15981743 | V36: 0.10113771 | W36: 0.10102575 | X36: 0.10280445 | Y36: 0.086046278 | Z36: 0.078643224 | AA36: 0.097966884 | AB36: 0.099657473 | AC36: 0.10049095 | AD36: 0.10569244 | AE36: 0.093915694 | AF36: 0.089311929 | AG36: 0.10426786 | AH36: 0.10889322 | AI36: 0.10922778 | AJ36: 0.098858677 | AK36: 0.097612234 | AL36: 0.091501615 | AM36: 0.10778407 | AN36: 0.10033403 | AO36: 0.11460478 | AP36: 0.10719257 | AQ36: 0.1192305 | AR36: 0.12236065 | AS36: 0.11975512
